<sdf version='1.6'>
  <world name='default'>
    <light name='sun' type='directional'>
      <cast_shadows>1</cast_shadows>
      <pose frame=''>0 0 10 0 -0 0</pose>
      <diffuse>0.8 0.8 0.8 1</diffuse>
      <specular>0.2 0.2 0.2 1</specular>
      <attenuation>
        <range>1000</range>
        <constant>0.9</constant>
        <linear>0.01</linear>
        <quadratic>0.001</quadratic>
      </attenuation>
      <direction>-0.5 0.1 -0.9</direction>
    </light>
    <model name='ground_plane'>
      <static>1</static>
      <link name='link'>
        <collision name='collision'>
          <geometry>
            <plane>
              <normal>0 0 1</normal>
              <size>5000 5000</size>
            </plane>
          </geometry>
          <surface>
            <contact>
              <collide_bitmask>65535</collide_bitmask>
              <ode/>
            </contact>
            <friction>
              <ode>
                <mu>100</mu>
                <mu2>50</mu2>
              </ode>
              <torsional>
                <ode/>
              </torsional>
            </friction>
            <bounce/>
          </surface>
          <max_contacts>10</max_contacts>
        </collision>
        <visual name='visual'>
          <pose frame=''>0 0 -0.1 0 -0 0</pose>
          <cast_shadows>0</cast_shadows>
          <geometry>
            <plane>
              <normal>0 0 1</normal>
              <size>5000 5000</size>
            </plane>
          </geometry>
          <material>
            <script>
              <uri>file://media/materials/scripts/gazebo.material</uri>
              <name>Gazebo/Grass</name>
            </script>
          </material>
        </visual>
        <self_collide>0</self_collide>
        <enable_wind>0</enable_wind>
        <kinematic>0</kinematic>
      </link>
    </model>
    <road name='Road'>
      <width>8</width>
      <point>-10 0 0</point>
      <point>100 0 0</point>
      <material>
        <script>
          <uri>file://media/materials/scripts/gazebo.material</uri>
          <name>Gazebo/Residential</name>
        </script>
      </material>
    </road>
    <road name='Sidewalk'>
      <width>1</width>
      <point>-10.5 -4.5 0</point>
      <point>100 -4.5 0</point>
      <point>100 4.5 0</point>
      <point>-10.5 4.5 0</point>
      <point>-10.5 -5 0</point>
      <material>
        <script>
          <uri>file://media/materials/scripts/gazebo.material</uri>
          <name>Gazebo/Footway</name>
        </script>
      </material>
    </road>
    <model name='prius'>
      <link name='base_link'>
        <pose frame=''>0 0 0 0 -0 0</pose>
        <inertial>
          <pose frame=''>0 0 0 0 -0 0</pose>
          <mass>1</mass>
          <inertia>
            <ixx>0.001</ixx>
            <ixy>0</ixy>
            <ixz>0</ixz>
            <iyy>0.001</iyy>
            <iyz>0</iyz>
            <izz>0.001</izz>
          </inertia>
        </inertial>
        <self_collide>0</self_collide>
        <enable_wind>0</enable_wind>
        <kinematic>0</kinematic>
      </link>
      <link name='chassis'>
        <pose frame=''>1.45 0 0 0 -0 1.57</pose>
        <inertial>
          <pose frame=''>-0 -0.002735 0.483209 0 -0 1.5708</pose>
          <mass>1371</mass>
          <inertia>
            <ixx>2591.3</ixx>
            <ixy>0.000184475</ixy>
            <ixz>-0.702035</ixz>
            <iyy>651.702</iyy>
            <iyz>2.57872e-06</iyz>
            <izz>2744.57</izz>
          </inertia>
        </inertial>
        <collision name='chassis_collision'>
          <pose frame=''>0 0.05 0.625 0 -0 0</pose>
          <geometry>
            <box>
              <size>1.7526 2.1 0.95</size>
            </box>
          </geometry>
          <max_contacts>10</max_contacts>
          <surface>
            <contact>
              <ode/>
            </contact>
            <bounce/>
            <friction>
              <torsional>
                <ode/>
              </torsional>
              <ode/>
            </friction>
          </surface>
        </collision>
        <collision name='chassis_fixed_joint_lump__front_bumper_collision_1'>
          <pose frame=''>0 -2 0.458488 0 -0 0</pose>
          <geometry>
            <box>
              <size>1.33728 0.48 0.566691</size>
            </box>
          </geometry>
          <max_contacts>10</max_contacts>
          <surface>
            <contact>
              <ode/>
            </contact>
            <bounce/>
            <friction>
              <torsional>
                <ode/>
              </torsional>
              <ode/>
            </friction>
          </surface>
        </collision>
        <collision name='chassis_fixed_joint_lump__hood_collision_2'>
          <pose frame=''>0 -1.90084 0.676305 0.341247 -0 0</pose>
          <geometry>
            <box>
              <size>1.59797 0.493107 0.265468</size>
            </box>
          </geometry>
          <max_contacts>10</max_contacts>
          <surface>
            <contact>
              <ode/>
            </contact>
            <bounce/>
            <friction>
              <torsional>
                <ode/>
              </torsional>
              <ode/>
            </friction>
          </surface>
        </collision>
        <collision name='chassis_fixed_joint_lump__windshield_collision_3'>
          <pose frame=''>0 -0.875105 1.03227 0.335476 -0 0</pose>
          <geometry>
            <box>
              <size>1.16838 1.65425 0.272347</size>
            </box>
          </geometry>
          <max_contacts>10</max_contacts>
          <surface>
            <contact>
              <ode/>
            </contact>
            <bounce/>
            <friction>
              <torsional>
                <ode/>
              </torsional>
              <ode/>
            </friction>
          </surface>
        </collision>
        <collision name='chassis_fixed_joint_lump__top_front_collision_4'>
          <pose frame=''>0 0.161236 1.38604 0.13503 -0 0</pose>
          <geometry>
            <box>
              <size>1.27915 0.625988 0.171868</size>
            </box>
          </geometry>
          <max_contacts>10</max_contacts>
          <surface>
            <contact>
              <ode/>
            </contact>
            <bounce/>
            <friction>
              <torsional>
                <ode/>
              </torsional>
              <ode/>
            </friction>
          </surface>
        </collision>
        <collision name='chassis_fixed_joint_lump__top_rear_collision_5'>
          <pose frame=''>0 0.817696 1.36007 -0.068997 0 0</pose>
          <geometry>
            <box>
              <size>1.28513 0.771189 0.226557</size>
            </box>
          </geometry>
          <max_contacts>10</max_contacts>
          <surface>
            <contact>
              <ode/>
            </contact>
            <bounce/>
            <friction>
              <torsional>
                <ode/>
              </torsional>
              <ode/>
            </friction>
          </surface>
        </collision>
        <collision name='chassis_fixed_joint_lump__rear_window_collision_6'>
          <pose frame=''>0 1.64053 1.17513 -0.262017 0 0</pose>
          <geometry>
            <box>
              <size>1.26785 1.11634 0.244286</size>
            </box>
          </geometry>
          <max_contacts>10</max_contacts>
          <surface>
            <contact>
              <ode/>
            </contact>
            <bounce/>
            <friction>
              <torsional>
                <ode/>
              </torsional>
              <ode/>
            </friction>
          </surface>
        </collision>
        <collision name='chassis_fixed_joint_lump__trunk_collision_7'>
          <pose frame=''>0 1.63706 0.88818 0 -0 0</pose>
          <geometry>
            <box>
              <size>1.78806 1.13899 0.482746</size>
            </box>
          </geometry>
          <max_contacts>10</max_contacts>
          <surface>
            <contact>
              <ode/>
            </contact>
            <bounce/>
            <friction>
              <torsional>
                <ode/>
              </torsional>
              <ode/>
            </friction>
          </surface>
        </collision>
        <collision name='chassis_fixed_joint_lump__back_bumper_collision_8'>
          <pose frame=''>0 2.05445 0.57787 0 -0 0</pose>
          <geometry>
            <box>
              <size>1.78165 0.512093 0.581427</size>
            </box>
          </geometry>
          <max_contacts>10</max_contacts>
          <surface>
            <contact>
              <ode/>
            </contact>
            <bounce/>
            <friction>
              <torsional>
                <ode/>
              </torsional>
              <ode/>
            </friction>
          </surface>
        </collision>
        <visual name='chassis_visual'>
          <pose frame=''>0 0 0 0 -0 0</pose>
          <geometry>
            <mesh>
              <scale>0.01 0.01 0.01</scale>
              <uri>model://../../prius_description/meshes/hybrid_body.obj</uri>
            </mesh>
          </geometry>
        </visual>
        <velocity_decay/>
        <sensor name='center_laser_sensor' type='ray'>
          <ray>
            <scan>
              <horizontal>
                <samples>512</samples>
                <resolution>1</resolution>
                <min_angle>-3.14</min_angle>
                <max_angle>3.14</max_angle>
              </horizontal>
              <vertical>
                <samples>32</samples>
                <min_angle>-0.05</min_angle>
                <max_angle>-0.35</max_angle>
              </vertical>
            </scan>
            <range>
              <min>0.2</min>
              <max>80</max>
              <resolution>0.01</resolution>
            </range>
          </ray>
          <plugin name='center_laser' filename='libgazebo_ros_block_laser.so'>
            <topicName>/prius/center_laser/scan</topicName>
            <frameName>center_laser_link</frameName>
            <gaussianNoise>0.01</gaussianNoise>
            <robotNamespace>/</robotNamespace>
          </plugin>
          <always_on>1</always_on>
          <update_rate>30</update_rate>
          <visualize>0</visualize>
          <pose frame=''>0 0.4 1.8 0 0 -1.5707</pose>
        </sensor>
        <gravity>1</gravity>
        <velocity_decay/>
        <sensor name='front_camera_sensor' type='camera'>
          <update_rate>30</update_rate>
          <camera name='front_camera'>
            <horizontal_fov>1.39626</horizontal_fov>
            <image>
              <width>800</width>
              <height>800</height>
              <format>R8G8B8</format>
            </image>
            <clip>
              <near>0.02</near>
              <far>300</far>
            </clip>
            <noise>
              <type>gaussian</type>
              <mean>0</mean>
              <stddev>0.007</stddev>
            </noise>
          </camera>
          <plugin name='front_camera_controller' filename='libgazebo_ros_camera.so'>
            <alwaysOn>1</alwaysOn>
            <updateRate>0.0</updateRate>
            <cameraName>/prius/front_camera</cameraName>
            <imageTopicName>image_raw</imageTopicName>
            <cameraInfoTopicName>/prius/front_camera_info</cameraInfoTopicName>
            <frameName>camera_link</frameName>
            <hackBaseline>0.07</hackBaseline>
            <distortionK1>0.0</distortionK1>
            <distortionK2>0.0</distortionK2>
            <distortionK3>0.0</distortionK3>
            <distortionT1>0.0</distortionT1>
            <distortionT2>0.0</distortionT2>
            <robotNamespace>/</robotNamespace>
          </plugin>
          <pose frame=''>0 -0.4 1.4 0 0.05 -1.5707</pose>
        </sensor>
        <self_collide>0</self_collide>
        <enable_wind>0</enable_wind>
        <kinematic>0</kinematic>
      </link>
      <joint name='base_link_connection' type='revolute'>
        <child>chassis</child>
        <parent>base_link</parent>
        <axis>
          <limit>
            <lower>0</lower>
            <upper>0</upper>
          </limit>
          <dynamics>
            <damping>0</damping>
            <friction>0</friction>
            <spring_reference>0</spring_reference>
            <spring_stiffness>0</spring_stiffness>
          </dynamics>
          <use_parent_model_frame>1</use_parent_model_frame>
          <xyz>0 0 1</xyz>
        </axis>
        <physics>
          <ode>
            <limit>
              <cfm>0</cfm>
              <erp>0.2</erp>
            </limit>
          </ode>
        </physics>
      </joint>
      <link name='fl_axle'>
        <pose frame=''>2.86061 0.765877 0.3 0 -0 1.57</pose>
        <inertial>
          <pose frame=''>0 0 0 0 -0 0</pose>
          <mass>1</mass>
          <inertia>
            <ixx>0.004</ixx>
            <ixy>0</ixy>
            <ixz>0</ixz>
            <iyy>0.004</iyy>
            <iyz>0</iyz>
            <izz>0.004</izz>
          </inertia>
        </inertial>
        <self_collide>0</self_collide>
        <enable_wind>0</enable_wind>
        <kinematic>0</kinematic>
      </link>
      <joint name='front_left_steer_joint' type='revolute'>
        <child>fl_axle</child>
        <parent>chassis</parent>
        <axis>
          <xyz>0 0 1</xyz>
          <limit>
            <lower>-1e+16</lower>
            <upper>1e+16</upper>
          </limit>
          <dynamics>
            <spring_reference>0</spring_reference>
            <spring_stiffness>0</spring_stiffness>
          </dynamics>
          <use_parent_model_frame>1</use_parent_model_frame>
        </axis>
      </joint>
      <link name='front_left_wheel'>
        <pose frame=''>2.86061 0.765877 0.3 0 -0 1.57</pose>
        <inertial>
          <pose frame=''>0 0 0 0 -0 0</pose>
          <mass>11</mass>
          <inertia>
            <ixx>0.586312</ixx>
            <ixy>0</ixy>
            <ixz>0</ixz>
            <iyy>0.335529</iyy>
            <iyz>0</iyz>
            <izz>0.335529</izz>
          </inertia>
        </inertial>
        <collision name='front_left_wheel_collision_collision'>
          <pose frame=''>0 0 0 0 -0 0</pose>
          <geometry>
            <sphere>
              <radius>0.31265</radius>
            </sphere>
          </geometry>
          <surface>
            <contact>
              <ode>
                <kp>1e+08</kp>
                <min_depth>0.005</min_depth>
              </ode>
            </contact>
            <friction>
              <ode>
                <mu>0.9</mu>
                <mu2>0.9</mu2>
              </ode>
              <torsional>
                <ode/>
              </torsional>
            </friction>
            <bounce/>
          </surface>
          <max_contacts>10</max_contacts>
        </collision>
        <visual name='front_left_wheel_visual'>
          <pose frame=''>0 0 0 0 -0 0</pose>
          <geometry>
            <mesh>
              <scale>0.01 0.01 0.01</scale>
              <uri>model://../../prius_description/meshes/wheel.obj</uri>
            </mesh>
          </geometry>
          <material>
            <script>
              <uri>__default__</uri>
              <name>__default__</name>
            </script>
          </material>
        </visual>
        <gravity>1</gravity>
        <velocity_decay/>
        <self_collide>0</self_collide>
        <enable_wind>0</enable_wind>
        <kinematic>0</kinematic>
      </link>
      <joint name='front_left_wheel_joint' type='revolute'>
        <child>front_left_wheel</child>
        <parent>fl_axle</parent>
        <axis>
          <xyz>0.000796 1 0</xyz>
          <limit>
            <lower>-1e+16</lower>
            <upper>1e+16</upper>
          </limit>
          <dynamics>
            <spring_reference>0</spring_reference>
            <spring_stiffness>0</spring_stiffness>
          </dynamics>
          <use_parent_model_frame>1</use_parent_model_frame>
        </axis>
      </joint>
      <link name='fr_axle'>
        <pose frame=''>2.85939 -0.768123 0.3 0 -0 1.57</pose>
        <inertial>
          <pose frame=''>0 0 0 0 -0 0</pose>
          <mass>1</mass>
          <inertia>
            <ixx>0.004</ixx>
            <ixy>0</ixy>
            <ixz>0</ixz>
            <iyy>0.004</iyy>
            <iyz>0</iyz>
            <izz>0.004</izz>
          </inertia>
        </inertial>
        <self_collide>0</self_collide>
        <enable_wind>0</enable_wind>
        <kinematic>0</kinematic>
      </link>
      <joint name='front_right_steer_joint' type='revolute'>
        <child>fr_axle</child>
        <parent>chassis</parent>
        <axis>
          <xyz>0 0 1</xyz>
          <limit>
            <lower>-1e+16</lower>
            <upper>1e+16</upper>
          </limit>
          <dynamics>
            <spring_reference>0</spring_reference>
            <spring_stiffness>0</spring_stiffness>
          </dynamics>
          <use_parent_model_frame>1</use_parent_model_frame>
        </axis>
      </joint>
      <link name='front_right_wheel'>
        <pose frame=''>2.85939 -0.768123 0.3 0 -0 1.57</pose>
        <inertial>
          <pose frame=''>0 0 0 0 -0 0</pose>
          <mass>11</mass>
          <inertia>
            <ixx>0.586312</ixx>
            <ixy>0</ixy>
            <ixz>0</ixz>
            <iyy>0.335529</iyy>
            <iyz>0</iyz>
            <izz>0.335529</izz>
          </inertia>
        </inertial>
        <collision name='front_right_wheel_collision_collision'>
          <pose frame=''>0 0 0 0 -0 0</pose>
          <geometry>
            <sphere>
              <radius>0.31265</radius>
            </sphere>
          </geometry>
          <surface>
            <contact>
              <ode>
                <kp>1e+08</kp>
                <min_depth>0.005</min_depth>
              </ode>
            </contact>
            <friction>
              <ode>
                <mu>0.9</mu>
                <mu2>0.9</mu2>
              </ode>
              <torsional>
                <ode/>
              </torsional>
            </friction>
            <bounce/>
          </surface>
          <max_contacts>10</max_contacts>
        </collision>
        <visual name='front_right_wheel_visual'>
          <pose frame=''>0 0 0 0 -0 0</pose>
          <geometry>
            <mesh>
              <scale>0.01 0.01 0.01</scale>
              <uri>model://../../prius_description/meshes/wheel.obj</uri>
            </mesh>
          </geometry>
          <material>
            <script>
              <uri>__default__</uri>
              <name>__default__</name>
            </script>
          </material>
        </visual>
        <gravity>1</gravity>
        <velocity_decay/>
        <self_collide>0</self_collide>
        <enable_wind>0</enable_wind>
        <kinematic>0</kinematic>
      </link>
      <joint name='front_right_wheel_joint' type='revolute'>
        <child>front_right_wheel</child>
        <parent>fr_axle</parent>
        <axis>
          <xyz>0.000796 1 0</xyz>
          <limit>
            <lower>-1e+16</lower>
            <upper>1e+16</upper>
          </limit>
          <dynamics>
            <spring_reference>0</spring_reference>
            <spring_stiffness>0</spring_stiffness>
          </dynamics>
          <use_parent_model_frame>1</use_parent_model_frame>
        </axis>
      </joint>
      <link name='rear_left_wheel'>
        <pose frame=''>0.000632 0.794154 0.3 0 -0 1.57</pose>
        <inertial>
          <pose frame=''>0 0 0 0 -0 0</pose>
          <mass>11</mass>
          <inertia>
            <ixx>0.586312</ixx>
            <ixy>0</ixy>
            <ixz>0</ixz>
            <iyy>0.335529</iyy>
            <iyz>0</iyz>
            <izz>0.335529</izz>
          </inertia>
        </inertial>
        <collision name='rear_left_wheel_collision_collision'>
          <pose frame=''>0 0 0 0 -0 0</pose>
          <geometry>
            <sphere>
              <radius>0.31265</radius>
            </sphere>
          </geometry>
          <surface>
            <contact>
              <ode>
                <kp>1e+08</kp>
                <min_depth>0.005</min_depth>
              </ode>
            </contact>
            <friction>
              <ode>
                <mu>0.9</mu>
                <mu2>0.9</mu2>
              </ode>
              <torsional>
                <ode/>
              </torsional>
            </friction>
            <bounce/>
          </surface>
          <max_contacts>10</max_contacts>
        </collision>
        <visual name='rear_left_wheel_visual'>
          <pose frame=''>0 0 0 0 -0 0</pose>
          <geometry>
            <mesh>
              <scale>0.01 0.01 0.01</scale>
              <uri>model://../../prius_description/meshes/wheel.obj</uri>
            </mesh>
          </geometry>
          <material>
            <script>
              <uri>__default__</uri>
              <name>__default__</name>
            </script>
          </material>
        </visual>
        <gravity>1</gravity>
        <velocity_decay/>
        <self_collide>0</self_collide>
        <enable_wind>0</enable_wind>
        <kinematic>0</kinematic>
      </link>
      <joint name='rear_left_wheel_joint' type='revolute'>
        <child>rear_left_wheel</child>
        <parent>chassis</parent>
        <axis>
          <xyz>0.000796 1 0</xyz>
          <limit>
            <lower>-1e+16</lower>
            <upper>1e+16</upper>
          </limit>
          <dynamics>
            <spring_reference>0</spring_reference>
            <spring_stiffness>0</spring_stiffness>
          </dynamics>
          <use_parent_model_frame>1</use_parent_model_frame>
        </axis>
      </joint>
      <link name='rear_right_wheel'>
        <pose frame=''>-0.000631 -0.791845 0.3 0 -0 1.57</pose>
        <inertial>
          <pose frame=''>0 0 0 0 -0 0</pose>
          <mass>11</mass>
          <inertia>
            <ixx>0.586312</ixx>
            <ixy>0</ixy>
            <ixz>0</ixz>
            <iyy>0.335529</iyy>
            <iyz>0</iyz>
            <izz>0.335529</izz>
          </inertia>
        </inertial>
        <collision name='rear_right_wheel_collision_collision'>
          <pose frame=''>0 0 0 0 -0 0</pose>
          <geometry>
            <sphere>
              <radius>0.31265</radius>
            </sphere>
          </geometry>
          <surface>
            <contact>
              <ode>
                <kp>1e+08</kp>
                <min_depth>0.005</min_depth>
              </ode>
            </contact>
            <friction>
              <ode>
                <mu>0.9</mu>
                <mu2>0.9</mu2>
              </ode>
              <torsional>
                <ode/>
              </torsional>
            </friction>
            <bounce/>
          </surface>
          <max_contacts>10</max_contacts>
        </collision>
        <visual name='rear_right_wheel_visual'>
          <pose frame=''>0 0 0 0 -0 0</pose>
          <geometry>
            <mesh>
              <scale>0.01 0.01 0.01</scale>
              <uri>model://../../prius_description/meshes/wheel.obj</uri>
            </mesh>
          </geometry>
          <material>
            <script>
              <uri>__default__</uri>
              <name>__default__</name>
            </script>
          </material>
        </visual>
        <gravity>1</gravity>
        <velocity_decay/>
        <self_collide>0</self_collide>
        <enable_wind>0</enable_wind>
        <kinematic>0</kinematic>
      </link>
      <joint name='rear_right_wheel_joint' type='revolute'>
        <child>rear_right_wheel</child>
        <parent>chassis</parent>
        <axis>
          <xyz>0.000796 1 0</xyz>
          <limit>
            <lower>-1e+16</lower>
            <upper>1e+16</upper>
          </limit>
          <dynamics>
            <spring_reference>0</spring_reference>
            <spring_stiffness>0</spring_stiffness>
          </dynamics>
          <use_parent_model_frame>1</use_parent_model_frame>
        </axis>
      </joint>
      <link name='steering_wheel'>
        <pose frame=''>2.07815 0.357234 0.988243 -1.3021 0 1.57</pose>
        <inertial>
          <pose frame=''>0 0 0 0 -0 0</pose>
          <mass>1</mass>
          <inertia>
            <ixx>0.145833</ixx>
            <ixy>0</ixy>
            <ixz>0</ixz>
            <iyy>0.145833</iyy>
            <iyz>0</iyz>
            <izz>0.125</izz>
          </inertia>
        </inertial>
        <visual name='steering_wheel_visual'>
          <pose frame=''>0 0 0 1.3021 -0 0</pose>
          <geometry>
            <mesh>
              <scale>0.01 0.01 0.01</scale>
              <uri>model://../../prius_description/meshes/steering_wheel.obj</uri>
            </mesh>
          </geometry>
        </visual>
        <self_collide>0</self_collide>
        <enable_wind>0</enable_wind>
        <kinematic>0</kinematic>
      </link>
      <joint name='steering_joint' type='revolute'>
        <child>steering_wheel</child>
        <parent>chassis</parent>
        <axis>
          <xyz>-0.964118 0.000768 0.265474</xyz>
          <limit>
            <lower>-1e+16</lower>
            <upper>1e+16</upper>
          </limit>
          <dynamics>
            <spring_reference>0</spring_reference>
            <spring_stiffness>0</spring_stiffness>
          </dynamics>
          <use_parent_model_frame>1</use_parent_model_frame>
        </axis>
      </joint>
      <plugin name='pruis_hybrid_drive' filename='libPriusHybridPlugin.so'>
        <chassis>chassis</chassis>
        <front_left_wheel>front_left_wheel_joint</front_left_wheel>
        <front_right_wheel>front_right_wheel_joint</front_right_wheel>
        <front_left_wheel_steering>front_left_steer_joint</front_left_wheel_steering>
        <front_right_wheel_steering>front_right_steer_joint</front_right_wheel_steering>
        <back_left_wheel>rear_left_wheel_joint</back_left_wheel>
        <back_right_wheel>rear_right_wheel_joint</back_right_wheel>
        <steering_wheel>steering_joint</steering_wheel>
        <chassis_aero_force_gain>0.63045</chassis_aero_force_gain>
        <front_torque>859.4004393000001</front_torque>
        <back_torque>0</back_torque>
        <front_brake_torque>1031.28052716</front_brake_torque>
        <back_brake_torque>687.5203514400001</back_brake_torque>
        <max_speed>5</max_speed>
        <min_gas_flow>8.981854013171626e-05</min_gas_flow>
        <gas_efficiency>0.371</gas_efficiency>
        <battery_charge_watt_hours>291</battery_charge_watt_hours>
        <battery_discharge_watt_hours>214</battery_discharge_watt_hours>
        <max_steer>0.6458</max_steer>
        <flwheel_steering_p_gain>1e4</flwheel_steering_p_gain>
        <frwheel_steering_p_gain>1e4</frwheel_steering_p_gain>
        <flwheel_steering_i_gain>0</flwheel_steering_i_gain>
        <frwheel_steering_i_gain>0</frwheel_steering_i_gain>
        <flwheel_steering_d_gain>3e2</flwheel_steering_d_gain>
        <frwheel_steering_d_gain>3e2</frwheel_steering_d_gain>
        <robotNamespace>/</robotNamespace>
      </plugin>
      <plugin name='joint_state_publisher' filename='libgazebo_ros_joint_state_publisher.so'>
        <jointName>rear_right_wheel_joint, rear_left_wheel_joint, front_right_wheel_joint, front_left_wheel_joint, front_right_steer_joint, front_left_steer_joint, steering_joint</jointName>
        <updateRate>100.0</updateRate>
        <alwaysOn>1</alwaysOn>
        <robotNamespace>/</robotNamespace>
      </plugin>
      <static>0</static>
      <plugin name='p3d' filename='libgazebo_ros_p3d.so'>
        <bodyName>base_link</bodyName>
        <topicName>base_pose_ground_truth</topicName>
        <frameName>map</frameName>
        <updateRate>100.0</updateRate>
        <robotNamespace>/</robotNamespace>
      </plugin>
      <pose frame=''>-40 -1.9 5.01 0 -0 0</pose>
    </model>
    <gravity>0 0 -9.8</gravity>
    <magnetic_field>6e-06 2.3e-05 -4.2e-05</magnetic_field>
    <atmosphere type='adiabatic'/>
    <physics name='default_physics' default='0' type='ode'>
      <max_step_size>0.001</max_step_size>
      <real_time_factor>1</real_time_factor>
      <real_time_update_rate>1000</real_time_update_rate>
    </physics>
    <scene>
      <ambient>0.4 0.4 0.4 1</ambient>
      <background>0.7 0.7 0.7 1</background>
      <shadows>1</shadows>
      <sky>
        <clouds>
          <speed>12</speed>
        </clouds>
      </sky>
    </scene>
    <wind/>
    <spherical_coordinates>
      <surface_model>EARTH_WGS84</surface_model>
      <latitude_deg>0</latitude_deg>
      <longitude_deg>0</longitude_deg>
      <elevation>0</elevation>
      <heading_deg>0</heading_deg>
    </spherical_coordinates>
    <state world_name='default'>
      <sim_time>590 484000000</sim_time>
      <real_time>233 385480963</real_time>
      <wall_time>1573069544 517237891</wall_time>
      <iterations>76479</iterations>
      <model name='Lamp Post'>
        <pose frame=''>1.99282 4.9148 0 0 -0 0</pose>
        <scale>1 1 1</scale>
        <link name='link'>
          <pose frame=''>1.99282 4.9148 0 0 -0 0</pose>
          <velocity>0 0 0 0 -0 0</velocity>
          <acceleration>0 0 0 0 -0 0</acceleration>
          <wrench>0 0 0 0 -0 0</wrench>
        </link>
      </model>
      <model name='Lamp Post_0'>
        <pose frame=''>39.9451 4.97079 0 0 -0 0</pose>
        <scale>1 1 1</scale>
        <link name='link'>
          <pose frame=''>39.9451 4.97079 0 0 -0 0</pose>
          <velocity>0 0 0 0 -0 0</velocity>
          <acceleration>0 0 0 0 -0 0</acceleration>
          <wrench>0 0 0 0 -0 0</wrench>
        </link>
      </model>
      <model name='Lamp Post_1'>
        <pose frame=''>78.919 5.00202 0 0 -0 0</pose>
        <scale>1 1 1</scale>
        <link name='link'>
          <pose frame=''>78.919 5.00202 0 0 -0 0</pose>
          <velocity>0 0 0 0 -0 0</velocity>
          <acceleration>0 0 0 0 -0 0</acceleration>
          <wrench>0 0 0 0 -0 0</wrench>
        </link>
      </model>
      <model name='Lamp Post_2'>
        <pose frame=''>19.8443 -4.95923 0 0 -0 3.11343</pose>
        <scale>1 1 1</scale>
        <link name='link'>
          <pose frame=''>19.8443 -4.95923 0 0 -0 3.11343</pose>
          <velocity>0 0 0 0 -0 0</velocity>
          <acceleration>0 0 0 0 -0 0</acceleration>
          <wrench>0 0 0 0 -0 0</wrench>
        </link>
      </model>
      <model name='Lamp Post_3'>
        <pose frame=''>59.5538 -5.03404 0 0 -0 3.11532</pose>
        <scale>1 1 1</scale>
        <link name='link'>
          <pose frame=''>59.5538 -5.03404 0 0 -0 3.11532</pose>
          <velocity>0 0 0 0 -0 0</velocity>
          <acceleration>0 0 0 0 -0 0</acceleration>
          <wrench>0 0 0 0 -0 0</wrench>
        </link>
      </model>
      <model name='ground_plane'>
        <pose frame=''>0 0 0 0 -0 0</pose>
        <scale>1 1 1</scale>
        <link name='link'>
          <pose frame=''>0 0 0 0 -0 0</pose>
          <velocity>0 0 0 0 -0 0</velocity>
          <acceleration>0 0 0 0 -0 0</acceleration>
          <wrench>0 0 0 0 -0 0</wrench>
        </link>
      </model>
      <model name='person_walking'>
        <pose frame=''>10.9707 -4.49222 1e-06 -0 5e-06 4.4e-05</pose>
        <scale>1 1 1</scale>
        <link name='link'>
          <pose frame=''>10.9707 -4.49222 1e-06 -0 5e-06 4.4e-05</pose>
          <velocity>0 0 0 0 -0 0</velocity>
          <acceleration>-1.30951 0.004865 -0.241215 -0.004969 -1.37843 -0.00047</acceleration>
          <wrench>-104.76 0.389239 -19.2972 0 -0 0</wrench>
        </link>
      </model>
      <model name='prius'>
        <pose frame=''>-0.363884 -1.65163 0.0069 -1e-06 0.000238 -0.030299</pose>
        <scale>1 1 1</scale>
        <link name='base_link'>
          <pose frame=''>-0.363884 -1.65163 0.0069 -1e-06 0.000238 -0.030299</pose>
          <velocity>0.009374 -0.004668 -0.001893 -0.000365 -0.011328 0.042537</velocity>
          <acceleration>-5.23665 -1.00843 0.011059 0.006049 0.256002 -1.31714</acceleration>
          <wrench>-5.23665 -1.00843 0.011059 0 -0 0</wrench>
        </link>
        <link name='chassis'>
          <pose frame=''>1.08545 -1.69561 0.007484 4.5e-05 1e-06 1.53965</pose>
          <velocity>0.011168 -0.013948 -0.015409 -0.000182 -0.005127 -0.00955</velocity>
          <acceleration>-0.523651 -0.042911 -0.018715 0.013541 0.731877 -0.65025</acceleration>
          <wrench>-717.925 -58.8313 -25.658 0 -0 0</wrench>
        </link>
        <link name='fl_axle'>
          <pose frame=''>2.51879 -0.972874 0.307608 -0.007083 -0.001048 1.54102</pose>
          <velocity>0.004175 -0.025762 -0.02938 0.095386 -0.095457 -0.146768</velocity>
          <acceleration>-1.32076 2.61977 -0.038384 -1.68325 1.52606 -0.754699</acceleration>
          <wrench>-1.32076 2.61977 -0.038384 0 -0 0</wrench>
        </link>
        <link name='fr_axle'>
          <pose frame=''>2.47087 -2.50613 0.307608 0.002927 -0.000578 1.54096</pose>
          <velocity>-0.003178 -0.028953 -0.029318 -0.111775 0.191461 2.87397</velocity>
          <acceleration>-11.7528 -4.50146 -0.037268 1.55856 1.40917 -2.06542</acceleration>
          <wrench>-11.7528 -4.50146 -0.037268 0 -0 0</wrench>
        </link>
        <link name='front_left_wheel'>
          <pose frame=''>2.51879 -0.972874 0.307566 0.244359 -0.000777 1.54102</pose>
          <velocity>0.001142 -0.025696 -0.024659 0.081984 0.328451 -0.146752</velocity>
          <acceleration>-0.989851 2.68844 -0.094077 -0.826272 1.4075 1.94049</acceleration>
          <wrench>-10.8884 29.5728 -1.03485 0 -0 0</wrench>
        </link>
        <link name='front_right_wheel'>
          <pose frame=''>2.47087 -2.50613 0.307566 0.20677 -0.000426 1.54096</pose>
          <velocity>-0.003401 -0.028991 -0.024579 -0.087045 -0.011293 2.87374</velocity>
          <acceleration>-12.0431 -4.6074 -0.088132 -1.5067 -0.454117 0.74317</acceleration>
          <wrench>-132.474 -50.6814 -0.969447 0 -0 0</wrench>
        </link>
        <link name='rear_left_wheel'>
          <pose frame=''>-0.339189 -0.857855 0.307555 2.09076 0.000122 1.53965</pose>
          <velocity>0.017108 -0.000303 -0.023611 0.001287 0.053405 -0.009558</velocity>
          <acceleration>0.017458 0.673176 0.214579 2.58483 0.083682 -0.64716</acceleration>
          <wrench>0.192033 7.40494 2.36037 0 -0 0</wrench>
        </link>
        <link name='rear_right_wheel'>
          <pose frame=''>-0.388532 -2.44308 0.307555 -0.072247 1.5e-05 1.53965</pose>
          <velocity>0.002108 0.000141 -0.023535 -0.000418 0.006484 -0.009552</velocity>
          <acceleration>-0.635298 0.694837 0.231885 2.50166 -1.08414 -0.647555</acceleration>
          <wrench>-6.98827 7.64321 2.55074 0 -0 0</wrench>
        </link>
        <link name='steering_wheel'>
          <pose frame=''>1.72419 -1.3576 0.995698 -1.30205 0 1.53965</pose>
          <velocity>0.009311 -0.019868 -0.012111 -0.000253 -0.005192 -0.009533</velocity>
          <acceleration>-0.204183 -0.451317 -0.137427 -0.167083 0.1884 -0.517571</acceleration>
          <wrench>-0.204183 -0.451317 -0.137427 0 -0 0</wrench>
        </link>
      </model>
      <light name='sun'>
        <pose frame=''>0 0 10 0 -0 0</pose>
      </light>
    </state>
    <gui fullscreen='0'>
      <camera name='user_camera'>
        <pose frame=''>2.65902 -3.02286 29.0658 -1e-06 1.5698 0.012171</pose>
        <view_controller>orbit</view_controller>
        <projection_type>perspective</projection_type>
      </camera>
    </gui>
    <model name='Lamp Post'>
      <static>1</static>
      <link name='link'>
        <collision name='collision'>
          <geometry>
            <mesh>
              <uri>model://lamp_post/meshes/lamp_post.dae</uri>
              <scale>3 3 3</scale>
            </mesh>
          </geometry>
          <max_contacts>10</max_contacts>
          <surface>
            <contact>
              <ode/>
            </contact>
            <bounce/>
            <friction>
              <torsional>
                <ode/>
              </torsional>
              <ode/>
            </friction>
          </surface>
        </collision>
        <visual name='visual'>
          <geometry>
            <mesh>
              <uri>model://lamp_post/meshes/lamp_post.dae</uri>
              <scale>3 3 3</scale>
            </mesh>
          </geometry>
        </visual>
        <self_collide>0</self_collide>
        <enable_wind>0</enable_wind>
        <kinematic>0</kinematic>
      </link>
      <pose frame=''>1.99282 4.9148 0 0 -0 0</pose>
    </model>
    <model name='Lamp Post_0'>
      <static>1</static>
      <link name='link'>
        <collision name='collision'>
          <geometry>
            <mesh>
              <uri>model://lamp_post/meshes/lamp_post.dae</uri>
              <scale>3 3 3</scale>
            </mesh>
          </geometry>
          <max_contacts>10</max_contacts>
          <surface>
            <contact>
              <ode/>
            </contact>
            <bounce/>
            <friction>
              <torsional>
                <ode/>
              </torsional>
              <ode/>
            </friction>
          </surface>
        </collision>
        <visual name='visual'>
          <geometry>
            <mesh>
              <uri>model://lamp_post/meshes/lamp_post.dae</uri>
              <scale>3 3 3</scale>
            </mesh>
          </geometry>
        </visual>
        <self_collide>0</self_collide>
        <enable_wind>0</enable_wind>
        <kinematic>0</kinematic>
      </link>
      <pose frame=''>39.9451 4.97079 0 0 -0 0</pose>
    </model>
    <model name='Lamp Post_1'>
      <static>1</static>
      <link name='link'>
        <collision name='collision'>
          <geometry>
            <mesh>
              <uri>model://lamp_post/meshes/lamp_post.dae</uri>
              <scale>3 3 3</scale>
            </mesh>
          </geometry>
          <max_contacts>10</max_contacts>
          <surface>
            <contact>
              <ode/>
            </contact>
            <bounce/>
            <friction>
              <torsional>
                <ode/>
              </torsional>
              <ode/>
            </friction>
          </surface>
        </collision>
        <visual name='visual'>
          <geometry>
            <mesh>
              <uri>model://lamp_post/meshes/lamp_post.dae</uri>
              <scale>3 3 3</scale>
            </mesh>
          </geometry>
        </visual>
        <self_collide>0</self_collide>
        <enable_wind>0</enable_wind>
        <kinematic>0</kinematic>
      </link>
      <pose frame=''>78.919 5.00202 0 0 -0 0</pose>
    </model>
    <model name='Lamp Post_2'>
      <static>1</static>
      <link name='link'>
        <collision name='collision'>
          <geometry>
            <mesh>
              <uri>model://lamp_post/meshes/lamp_post.dae</uri>
              <scale>3 3 3</scale>
            </mesh>
          </geometry>
          <max_contacts>10</max_contacts>
          <surface>
            <contact>
              <ode/>
            </contact>
            <bounce/>
            <friction>
              <torsional>
                <ode/>
              </torsional>
              <ode/>
            </friction>
          </surface>
        </collision>
        <visual name='visual'>
          <geometry>
            <mesh>
              <uri>model://lamp_post/meshes/lamp_post.dae</uri>
              <scale>3 3 3</scale>
            </mesh>
          </geometry>
        </visual>
        <self_collide>0</self_collide>
        <enable_wind>0</enable_wind>
        <kinematic>0</kinematic>
      </link>
      <pose frame=''>19.8443 -4.95923 0 0 -0 0</pose>
    </model>
    <model name='Lamp Post_3'>
      <static>1</static>
      <link name='link'>
        <collision name='collision'>
          <geometry>
            <mesh>
              <uri>model://lamp_post/meshes/lamp_post.dae</uri>
              <scale>3 3 3</scale>
            </mesh>
          </geometry>
          <max_contacts>10</max_contacts>
          <surface>
            <contact>
              <ode/>
            </contact>
            <bounce/>
            <friction>
              <torsional>
                <ode/>
              </torsional>
              <ode/>
            </friction>
          </surface>
        </collision>
        <visual name='visual'>
          <geometry>
            <mesh>
              <uri>model://lamp_post/meshes/lamp_post.dae</uri>
              <scale>3 3 3</scale>
            </mesh>
          </geometry>
        </visual>
        <self_collide>0</self_collide>
        <enable_wind>0</enable_wind>
        <kinematic>0</kinematic>
      </link>
      <pose frame=''>59.5538 -5.03404 0 0 -0 0</pose>
    </model>
    <model name='person_walking'>
      <link name='link'>
        <inertial>
          <pose frame=''>0 0 0.95 0 -0 0</pose>
          <mass>80</mass>
          <inertia>
            <ixx>27.82</ixx>
            <ixy>0</ixy>
            <ixz>0</ixz>
            <iyy>24.88</iyy>
            <iyz>0</iyz>
            <izz>4.57</izz>
          </inertia>
        </inertial>
        <collision name='bottom'>
          <pose frame=''>0 0 0.01 0 -0 0</pose>
          <geometry>
            <box>
              <size>0.35 0.75 0.02</size>
            </box>
          </geometry>
          <max_contacts>10</max_contacts>
          <surface>
            <contact>
              <ode/>
            </contact>
            <bounce/>
            <friction>
              <torsional>
                <ode/>
              </torsional>
              <ode/>
            </friction>
          </surface>
        </collision>
        <collision name='person'>
          <pose frame=''>0 0 -0.02 0 -0 0</pose>
          <geometry>
            <mesh>
              <uri>model://person_walking/meshes/walking.dae</uri>
            </mesh>
          </geometry>
          <max_contacts>10</max_contacts>
          <surface>
            <contact>
              <ode/>
            </contact>
            <bounce/>
            <friction>
              <torsional>
                <ode/>
              </torsional>
              <ode/>
            </friction>
          </surface>
        </collision>
        <visual name='visual'>
          <pose frame=''>0 0 -0.02 0 -0 0</pose>
          <geometry>
            <mesh>
              <uri>model://person_walking/meshes/walking.dae</uri>
            </mesh>
          </geometry>
        </visual>
        <self_collide>0</self_collide>
        <enable_wind>0</enable_wind>
        <kinematic>0</kinematic>
      </link>
      <pose frame=''>10.9707 -4.49061 0 0 -0 0</pose>
    </model>
  </world>
</sdf>
